Workbook
Name deal_name: Inputs!$B$5
Name deal_short_name: Inputs!$B$6
Name property_address_full: Inputs!$B$7
Name property_business_name: Inputs!$B$8
Name property_business_url: Inputs!$B$9
Name property_acres: Inputs!$B$10
Name purchase_price: Inputs!$B$12
Name earnest_money: Inputs!$B$13
Name reserve: Inputs!$B$14
Name title_fees: Inputs!$B$15
Name loan_costs_fixed: Inputs!$B$16
Name loan_costs_pct: Inputs!$B$17
Name loan_to_value: Inputs!$B$19
Name loan_interest_rate: Inputs!$B$20
Name loan_amortization_years: Inputs!$B$21
Name rent_year_1_monthly: Inputs!$B$23
Name rent_annual_escalator: Inputs!$B$24
Name mgmt_fee_pct_of_rent: Inputs!$B$25
Name rm_annual: Inputs!$B$26
Name misc_annual: Inputs!$B$27
Name property_tax_annual: Inputs!$B$28
Name insurance_annual: Inputs!$B$29
Name is_pure_nnn: Inputs!$B$30
Name hold_period_years: Inputs!$B$32
Name exit_cap_rate: Inputs!$B$33
Name sale_title_fee_pct: Inputs!$B$34
Name je_cash: Inputs!$B$36
Name je_repayment: Inputs!$B$37
Name je_credited_equity: Inputs!$B$38
Name em_allocation_mode: Inputs!$B$40
Name equity_required: 'The Buy'!$B$9
Name loan_amount: 'The Buy'!$B$12
Name monthly_payment: 'The Buy'!$B$15
Name annual_payment: 'The Buy'!$B$16
Name cum_principal_at_exit: 'The Buy'!$B$20

Sheet Summary
A1: MOAB EARLY APP — SUMMARY
A2: =property_address_full
A4: Purchase price | B4: =purchase_price
A5: Loan amount | B5: =loan_amount
A6: Equity required | B6: =equity_required
A7: Earnest money | B7: =earnest_money
A8: Reserve | B8: =reserve
A9: Year 1 rent (monthly) | B9: =rent_year_1_monthly
A10: Annual rent escalator | B10: =rent_annual_escalator
A11: Hold period (yrs) | B11: =hold_period_years
A12: Loan rate | B12: =loan_interest_rate
A13: Loan amortization | B13: =loan_amortization_years
A14: Monthly payment | B14: =monthly_payment
A15: Year 1 NOI | B15: =INDEX(NOI!B15:K15,1,1)
A16: Year 1 cash flow | B16: =INDEX(NOI!B19:K19,1,1)
A17: Year-N NOI (at hold) | B17: =INDEX(NOI!B15:K15,1,hold_period_years)
A18: Year-N sale value (at exit cap) | B18: =Sale!B4
A19: Year-N total profit | B19: =Sale!B11
A20: JE total profit (auto-ded slot) | B20: =SUMIFS(Sale!D15:D26,'Investor Team'!F5:F16,1)

Sheet Inputs
A1: MOAB EARLY APP — INPUTS
A2: Yellow cells = editable. App reads these on load. Names below match app field keys.
A4: DEAL META
A5: Deal name | B5: Moab Early — 805 N Main | C5: string
A6: Deal short name | B6: Able_Moab_Warehouse | C6: used in version filenames
A7: Property address (full) | B7: 805 N Main St, Moab, UT 84532 | C7: Google / Nominatim auto
A8: Property business name | C8: auto-pull from Maps
A9: Property business URL | C9: auto-pull from Maps
A10: Property acres | B10: 0.99 | C10: acres
A11: PURCHASE
A12: Purchase price | B12: 1225000 | C12: $
A13: Earnest money | B13: 25000 | C13: $
A14: Reserve | B14: 40000 | C14: $
A15: Title fees | B15: 2000 | C15: $
A16: Loan costs (fixed) | B16: 2000 | C16: $
A17: Loan costs (% of loan) | B17: 0.01 | C17: % of loan
A18: LOAN
A19: Loan-to-value | B19: 0.8 | C19: 60% – 85%
A20: Loan interest rate | B20: 0.075 | C20: 5% – 10%
A21: Loan amortization (yrs) | B21: 25 | C21: {15,20,25,30}
A22: OPERATING (Year 1, escalates)
A23: Year 1 rent (monthly NNN) | B23: 9000 | C23: $ / month
A24: Annual rent escalator | B24: 0.04 | C24: 0% – 6%
A25: Mgmt fee % of rent | B25: 0.04 | C25: % of gross rent
A26: R&M annual | B26: 0 | C26: $ / year
A27: Misc OpEx annual | B27: 6000 | C27: $ / year
A28: Property tax annual | B28: 11884 | C28: $ (only if NOT pure NNN)
A29: Insurance annual | B29: 1800 | C29: $ (only if NOT pure NNN)
A30: Pure NNN? (1 = TRUE) | B30: 1 | C30: 1 = tax+ins NOT in NOI
A31: EXIT
A32: Hold period (yrs) | B32: 5 | C32: 3 – 10
A33: Exit cap rate | B33: 0.08 | C33: 5% – 12%
A34: Sale title fee % | B34: 0.01 | C34: % of sale price
A35: JE POSITION (operator)
A36: JE cash (new) | B36: 0 | C36: $ new cash this round
A37: JE repayment of prior | B37: 175000 | C37: $ prior repaid at close
A38: JE credited equity | B38: 0 | C38: $ non-cash credit
A39: EARNEST MONEY ALLOCATION
A40: EM allocation mode (1/2/3) | B40: 1 | C40: 1=dedicated,2=distributed,3=JE-absorbed

Sheet NOI
A1: NOI — 10-YEAR PROJECTION
B3: Yr 1 | C3: Yr 2 | D3: Yr 3 | E3: Yr 4 | F3: Yr 5 | G3: Yr 6 | H3: Yr 7 | I3: Yr 8 | J3: Yr 9 | K3: Yr 10
A4: Monthly rent (NNN) | B4: =IF(1>hold_period_years,"",rent_year_1_monthly) | C4: =IF(2>hold_period_years,"",B4*(1+rent_annual_escalator)) | D4: =IF(3>hold_period_years,"",C4*(1+rent_annual_escalator)) | E4: =IF(4>hold_period_years,"",D4*(1+rent_annual_escalator)) | F4: =IF(5>hold_period_years,"",E4*(1+rent_annual_escalator)) | G4: =IF(6>hold_period_years,"",F4*(1+rent_annual_escalator)) | H4: =IF(7>hold_period_years,"",G4*(1+rent_annual_escalator)) | I4: =IF(8>hold_period_years,"",H4*(1+rent_annual_escalator)) | J4: =IF(9>hold_period_years,"",I4*(1+rent_annual_escalator)) | K4: =IF(10>hold_period_years,"",J4*(1+rent_annual_escalator))
A5: Annual rent | B5: =IF(1>hold_period_years,"",B4*12) | C5: =IF(2>hold_period_years,"",C4*12) | D5: =IF(3>hold_period_years,"",D4*12) | E5: =IF(4>hold_period_years,"",E4*12) | F5: =IF(5>hold_period_years,"",F4*12) | G5: =IF(6>hold_period_years,"",G4*12) | H5: =IF(7>hold_period_years,"",H4*12) | I5: =IF(8>hold_period_years,"",I4*12) | J5: =IF(9>hold_period_years,"",J4*12) | K5: =IF(10>hold_period_years,"",K4*12)
A7: OPERATING EXPENSES
A8: Mgmt fee | B8: =IF(1>hold_period_years,"",B5*mgmt_fee_pct_of_rent) | C8: =IF(2>hold_period_years,"",C5*mgmt_fee_pct_of_rent) | D8: =IF(3>hold_period_years,"",D5*mgmt_fee_pct_of_rent) | E8: =IF(4>hold_period_years,"",E5*mgmt_fee_pct_of_rent) | F8: =IF(5>hold_period_years,"",F5*mgmt_fee_pct_of_rent) | G8: =IF(6>hold_period_years,"",G5*mgmt_fee_pct_of_rent) | H8: =IF(7>hold_period_years,"",H5*mgmt_fee_pct_of_rent) | I8: =IF(8>hold_period_years,"",I5*mgmt_fee_pct_of_rent) | J8: =IF(9>hold_period_years,"",J5*mgmt_fee_pct_of_rent) | K8: =IF(10>hold_period_years,"",K5*mgmt_fee_pct_of_rent)
A9: R&M | B9: =IF(1>hold_period_years,"",rm_annual) | C9: =IF(2>hold_period_years,"",rm_annual) | D9: =IF(3>hold_period_years,"",rm_annual) | E9: =IF(4>hold_period_years,"",rm_annual) | F9: =IF(5>hold_period_years,"",rm_annual) | G9: =IF(6>hold_period_years,"",rm_annual) | H9: =IF(7>hold_period_years,"",rm_annual) | I9: =IF(8>hold_period_years,"",rm_annual) | J9: =IF(9>hold_period_years,"",rm_annual) | K9: =IF(10>hold_period_years,"",rm_annual)
A10: Misc OpEx | B10: =IF(1>hold_period_years,"",misc_annual) | C10: =IF(2>hold_period_years,"",misc_annual) | D10: =IF(3>hold_period_years,"",misc_annual) | E10: =IF(4>hold_period_years,"",misc_annual) | F10: =IF(5>hold_period_years,"",misc_annual) | G10: =IF(6>hold_period_years,"",misc_annual) | H10: =IF(7>hold_period_years,"",misc_annual) | I10: =IF(8>hold_period_years,"",misc_annual) | J10: =IF(9>hold_period_years,"",misc_annual) | K10: =IF(10>hold_period_years,"",misc_annual)
A11: Property tax | B11: =IF(1>hold_period_years,"",IF(is_pure_nnn=1,0,property_tax_annual)) | C11: =IF(2>hold_period_years,"",IF(is_pure_nnn=1,0,property_tax_annual)) | D11: =IF(3>hold_period_years,"",IF(is_pure_nnn=1,0,property_tax_annual)) | E11: =IF(4>hold_period_years,"",IF(is_pure_nnn=1,0,property_tax_annual)) | F11: =IF(5>hold_period_years,"",IF(is_pure_nnn=1,0,property_tax_annual)) | G11: =IF(6>hold_period_years,"",IF(is_pure_nnn=1,0,property_tax_annual)) | H11: =IF(7>hold_period_years,"",IF(is_pure_nnn=1,0,property_tax_annual)) | I11: =IF(8>hold_period_years,"",IF(is_pure_nnn=1,0,property_tax_annual)) | J11: =IF(9>hold_period_years,"",IF(is_pure_nnn=1,0,property_tax_annual)) | K11: =IF(10>hold_period_years,"",IF(is_pure_nnn=1,0,property_tax_annual))
A12: Insurance | B12: =IF(1>hold_period_years,"",IF(is_pure_nnn=1,0,insurance_annual)) | C12: =IF(2>hold_period_years,"",IF(is_pure_nnn=1,0,insurance_annual)) | D12: =IF(3>hold_period_years,"",IF(is_pure_nnn=1,0,insurance_annual)) | E12: =IF(4>hold_period_years,"",IF(is_pure_nnn=1,0,insurance_annual)) | F12: =IF(5>hold_period_years,"",IF(is_pure_nnn=1,0,insurance_annual)) | G12: =IF(6>hold_period_years,"",IF(is_pure_nnn=1,0,insurance_annual)) | H12: =IF(7>hold_period_years,"",IF(is_pure_nnn=1,0,insurance_annual)) | I12: =IF(8>hold_period_years,"",IF(is_pure_nnn=1,0,insurance_annual)) | J12: =IF(9>hold_period_years,"",IF(is_pure_nnn=1,0,insurance_annual)) | K12: =IF(10>hold_period_years,"",IF(is_pure_nnn=1,0,insurance_annual))
A13: Total OpEx | B13: =IF(1>hold_period_years,"",SUM(B8:B12)) | C13: =IF(2>hold_period_years,"",SUM(C8:C12)) | D13: =IF(3>hold_period_years,"",SUM(D8:D12)) | E13: =IF(4>hold_period_years,"",SUM(E8:E12)) | F13: =IF(5>hold_period_years,"",SUM(F8:F12)) | G13: =IF(6>hold_period_years,"",SUM(G8:G12)) | H13: =IF(7>hold_period_years,"",SUM(H8:H12)) | I13: =IF(8>hold_period_years,"",SUM(I8:I12)) | J13: =IF(9>hold_period_years,"",SUM(J8:J12)) | K13: =IF(10>hold_period_years,"",SUM(K8:K12))
A15: NOI | B15: =IF(1>hold_period_years,"",B5-B13) | C15: =IF(2>hold_period_years,"",C5-C13) | D15: =IF(3>hold_period_years,"",D5-D13) | E15: =IF(4>hold_period_years,"",E5-E13) | F15: =IF(5>hold_period_years,"",F5-F13) | G15: =IF(6>hold_period_years,"",G5-G13) | H15: =IF(7>hold_period_years,"",H5-H13) | I15: =IF(8>hold_period_years,"",I5-I13) | J15: =IF(9>hold_period_years,"",J5-J13) | K15: =IF(10>hold_period_years,"",K5-K13)
A17: Loan amount | B17: =IF(1>hold_period_years,"",purchase_price*loan_to_value) | C17: =IF(2>hold_period_years,"",purchase_price*loan_to_value) | D17: =IF(3>hold_period_years,"",purchase_price*loan_to_value) | E17: =IF(4>hold_period_years,"",purchase_price*loan_to_value) | F17: =IF(5>hold_period_years,"",purchase_price*loan_to_value) | G17: =IF(6>hold_period_years,"",purchase_price*loan_to_value) | H17: =IF(7>hold_period_years,"",purchase_price*loan_to_value) | I17: =IF(8>hold_period_years,"",purchase_price*loan_to_value) | J17: =IF(9>hold_period_years,"",purchase_price*loan_to_value) | K17: =IF(10>hold_period_years,"",purchase_price*loan_to_value)
A18: Annual debt service | B18: =IF(1>hold_period_years,"",-PMT(loan_interest_rate/12,loan_amortization_years*12,purchase_price*loan_to_value)*12) | C18: =IF(2>hold_period_years,"",-PMT(loan_interest_rate/12,loan_amortization_years*12,purchase_price*loan_to_value)*12) | D18: =IF(3>hold_period_years,"",-PMT(loan_interest_rate/12,loan_amortization_years*12,purchase_price*loan_to_value)*12) | E18: =IF(4>hold_period_years,"",-PMT(loan_interest_rate/12,loan_amortization_years*12,purchase_price*loan_to_value)*12) | F18: =IF(5>hold_period_years,"",-PMT(loan_interest_rate/12,loan_amortization_years*12,purchase_price*loan_to_value)*12) | G18: =IF(6>hold_period_years,"",-PMT(loan_interest_rate/12,loan_amortization_years*12,purchase_price*loan_to_value)*12) | H18: =IF(7>hold_period_years,"",-PMT(loan_interest_rate/12,loan_amortization_years*12,purchase_price*loan_to_value)*12) | I18: =IF(8>hold_period_years,"",-PMT(loan_interest_rate/12,loan_amortization_years*12,purchase_price*loan_to_value)*12) | J18: =IF(9>hold_period_years,"",-PMT(loan_interest_rate/12,loan_amortization_years*12,purchase_price*loan_to_value)*12) | K18: =IF(10>hold_period_years,"",-PMT(loan_interest_rate/12,loan_amortization_years*12,purchase_price*loan_to_value)*12)
A19: Cash flow (after debt) | B19: =IF(1>hold_period_years,"",B15-B18) | C19: =IF(2>hold_period_years,"",C15-C18) | D19: =IF(3>hold_period_years,"",D15-D18) | E19: =IF(4>hold_period_years,"",E15-E18) | F19: =IF(5>hold_period_years,"",F15-F18) | G19: =IF(6>hold_period_years,"",G15-G18) | H19: =IF(7>hold_period_years,"",H15-H18) | I19: =IF(8>hold_period_years,"",I15-I18) | J19: =IF(9>hold_period_years,"",J15-J18) | K19: =IF(10>hold_period_years,"",K15-K18)
A21: Property value (at exit cap) | B21: =IF(1>hold_period_years,"",B15/exit_cap_rate) | C21: =IF(2>hold_period_years,"",C15/exit_cap_rate) | D21: =IF(3>hold_period_years,"",D15/exit_cap_rate) | E21: =IF(4>hold_period_years,"",E15/exit_cap_rate) | F21: =IF(5>hold_period_years,"",F15/exit_cap_rate) | G21: =IF(6>hold_period_years,"",G15/exit_cap_rate) | H21: =IF(7>hold_period_years,"",H15/exit_cap_rate) | I21: =IF(8>hold_period_years,"",I15/exit_cap_rate) | J21: =IF(9>hold_period_years,"",J15/exit_cap_rate) | K21: =IF(10>hold_period_years,"",K15/exit_cap_rate)

Sheet The Buy
A1: THE BUY — Equity & Mortgage
A3: Purchase price | B3: =purchase_price
A4: Title fees | B4: =title_fees
A5: Earnest money | B5: =-earnest_money
A6: Loan costs | B6: =purchase_price*loan_to_value*loan_costs_pct + loan_costs_fixed
A7: Loan | B7: =-purchase_price*loan_to_value
A8: Reserve | B8: =reserve
A9: Equity required | B9: =SUM(B3:B8)
A11: Mortgage Calculator
A12: Loan amount | B12: =purchase_price*loan_to_value
A13: Annual interest rate | B13: =loan_interest_rate
A14: Amortization (yrs) | B14: =loan_amortization_years
A15: Monthly payment | B15: =-PMT(loan_interest_rate/12,loan_amortization_years*12,purchase_price*loan_to_value)
A16: Annual payment | B16: =B15*12
A17: Total payments | B17: =B15*loan_amortization_years*12
A18: Interest cost | B18: =B17-B12
A19: Annual principal (yr1) | B19: =B16-(B12*loan_interest_rate)
A20: Cumulative principal at exit | B20: =B19*hold_period_years

Sheet Investor Team
A1: INVESTOR TEAM — Cap Stack
A2: Yellow = editable. Equal-Lock Group: members with same group # split that group's combined % equally. Auto-Deduct: exactly one row's % auto-fills as 100% − sum(others).
A4: # | B4: Name | C4: Contribution | D4: Ownership % | E4: Group | F4: Auto-Deduct? | G4: Notes
A5: 1 | B5: John A | C5: 70000 | D5: 0.14 | E5: 1 | F5: 0
A6: 2 | B6: Nell | C6: 70000 | D6: 0.14 | E6: 1 | F6: 0
A7: 3 | B7: John C | C7: 70000 | D7: 0.14 | E7: 1 | F7: 0
A8: 4 | B8: Steve | C8: 70000 | D8: 0.14 | E8: 1 | F8: 0
A9: 5 | B9: Earnest Money | C9: 20000 | D9: 0.04 | F9: 0 | G9: Dedicated EM slot
A10: 6 | B10: John E (operator) | C10: 0 | D10: 0.4 | F10: 1 | G10: Auto-deduct: 100% − sum(others)
A11: 7
A12: 8
A13: 9
A14: 10
A15: 11
A16: 12
B18: TOTAL | C18: =SUM(C5:C16) | D18: =SUM(D5:D16)
B19: Sum to 100%? | D19: =IF(ROUND(D18,4)=1,"YES — OK to save","NO — fix before saving")

Sheet Sale
A1: SALE — Year-N Exit Waterfall
A3: Year-N NOI | B3: =INDEX(NOI!B15:K15,1,hold_period_years)
A4: Sale price (NOI / cap) | B4: =B3/exit_cap_rate
A5: Sale title fees | B5: =-B4*sale_title_fee_pct
A6: Loan payoff at exit | B6: =-(loan_amount-cum_principal_at_exit)
A8: Net cash to LLC | B8: =B4+B5+B6
A9: Equity returned | B9: =-SUM('Investor Team'!C5:C16)
A11: TOTAL PROFIT | B11: =B8+B9
A13: DISTRIBUTION BY INVESTOR
A14: Member | B14: Initial $ | C14: % Profit Share | D14: Profit
A15: ='Investor Team'!B5 | B15: ='Investor Team'!C5 | C15: ='Investor Team'!D5 | D15: =IF('Investor Team'!D5="",0,'Investor Team'!D5*$B$11)
A16: ='Investor Team'!B6 | B16: ='Investor Team'!C6 | C16: ='Investor Team'!D6 | D16: =IF('Investor Team'!D6="",0,'Investor Team'!D6*$B$11)
A17: ='Investor Team'!B7 | B17: ='Investor Team'!C7 | C17: ='Investor Team'!D7 | D17: =IF('Investor Team'!D7="",0,'Investor Team'!D7*$B$11)
A18: ='Investor Team'!B8 | B18: ='Investor Team'!C8 | C18: ='Investor Team'!D8 | D18: =IF('Investor Team'!D8="",0,'Investor Team'!D8*$B$11)
A19: ='Investor Team'!B9 | B19: ='Investor Team'!C9 | C19: ='Investor Team'!D9 | D19: =IF('Investor Team'!D9="",0,'Investor Team'!D9*$B$11)
A20: ='Investor Team'!B10 | B20: ='Investor Team'!C10 | C20: ='Investor Team'!D10 | D20: =IF('Investor Team'!D10="",0,'Investor Team'!D10*$B$11)
A21: ='Investor Team'!B11 | B21: ='Investor Team'!C11 | C21: ='Investor Team'!D11 | D21: =IF('Investor Team'!D11="",0,'Investor Team'!D11*$B$11)
A22: ='Investor Team'!B12 | B22: ='Investor Team'!C12 | C22: ='Investor Team'!D12 | D22: =IF('Investor Team'!D12="",0,'Investor Team'!D12*$B$11)
A23: ='Investor Team'!B13 | B23: ='Investor Team'!C13 | C23: ='Investor Team'!D13 | D23: =IF('Investor Team'!D13="",0,'Investor Team'!D13*$B$11)
A24: ='Investor Team'!B14 | B24: ='Investor Team'!C14 | C24: ='Investor Team'!D14 | D24: =IF('Investor Team'!D14="",0,'Investor Team'!D14*$B$11)
A25: ='Investor Team'!B15 | B25: ='Investor Team'!C15 | C25: ='Investor Team'!D15 | D25: =IF('Investor Team'!D15="",0,'Investor Team'!D15*$B$11)
A26: ='Investor Team'!B16 | B26: ='Investor Team'!C16 | C26: ='Investor Team'!D16 | D26: =IF('Investor Team'!D16="",0,'Investor Team'!D16*$B$11)

Sheet Sensitivity
A1: SENSITIVITY — How the deal moves under different inputs
A3: TABLE 1 — Year N sale value: rent × exit cap rate
A5: Yr1 Rent ↓ / Cap Rate → | B5: 0.06 | C5: 0.065 | D5: 0.07 | E5: 0.075 | F5: 0.08 | G5: 0.085 | H5: 0.09 | I5: 0.095 | J5: 0.1
A6: 7000 | B6: =(7000*(1+rent_annual_escalator)^(hold_period_years-1)*12 - (7000*(1+rent_annual_escalator)^(hold_period_years-1)*12*mgmt_fee_pct_of_rent + rm_annual + misc_annual + IF(is_pure_nnn=1,0,property_tax_annual+insurance_annual))) / 0.06 | C6: =(7000*(1+rent_annual_escalator)^(hold_period_years-1)*12 - (7000*(1+rent_annual_escalator)^(hold_period_years-1)*12*mgmt_fee_pct_of_rent + rm_annual + misc_annual + IF(is_pure_nnn=1,0,property_tax_annual+insurance_annual))) / 0.065 | D6: =(7000*(1+rent_annual_escalator)^(hold_period_years-1)*12 - (7000*(1+rent_annual_escalator)^(hold_period_years-1)*12*mgmt_fee_pct_of_rent + rm_annual + misc_annual + IF(is_pure_nnn=1,0,property_tax_annual+insurance_annual))) / 0.07 | E6: =(7000*(1+rent_annual_escalator)^(hold_period_years-1)*12 - (7000*(1+rent_annual_escalator)^(hold_period_years-1)*12*mgmt_fee_pct_of_rent + rm_annual + misc_annual + IF(is_pure_nnn=1,0,property_tax_annual+insurance_annual))) / 0.075 | F6: =(7000*(1+rent_annual_escalator)^(hold_period_years-1)*12 - (7000*(1+rent_annual_escalator)^(hold_period_years-1)*12*mgmt_fee_pct_of_rent + rm_annual + misc_annual + IF(is_pure_nnn=1,0,property_tax_annual+insurance_annual))) / 0.08 | G6: =(7000*(1+rent_annual_escalator)^(hold_period_years-1)*12 - (7000*(1+rent_annual_escalator)^(hold_period_years-1)*12*mgmt_fee_pct_of_rent + rm_annual + misc_annual + IF(is_pure_nnn=1,0,property_tax_annual+insurance_annual))) / 0.085 | H6: =(7000*(1+rent_annual_escalator)^(hold_period_years-1)*12 - (7000*(1+rent_annual_escalator)^(hold_period_years-1)*12*mgmt_fee_pct_of_rent + rm_annual + misc_annual + IF(is_pure_nnn=1,0,property_tax_annual+insurance_annual))) / 0.09 | I6: =(7000*(1+rent_annual_escalator)^(hold_period_years-1)*12 - (7000*(1+rent_annual_escalator)^(hold_period_years-1)*12*mgmt_fee_pct_of_rent + rm_annual + misc_annual + IF(is_pure_nnn=1,0,property_tax_annual+insurance_annual))) / 0.095 | J6: =(7000*(1+rent_annual_escalator)^(hold_period_years-1)*12 - (7000*(1+rent_annual_escalator)^(hold_period_years-1)*12*mgmt_fee_pct_of_rent + rm_annual + misc_annual + IF(is_pure_nnn=1,0,property_tax_annual+insurance_annual))) / 0.1
A7: 7500 | B7: =(7500*(1+rent_annual_escalator)^(hold_period_years-1)*12 - (7500*(1+rent_annual_escalator)^(hold_period_years-1)*12*mgmt_fee_pct_of_rent + rm_annual + misc_annual + IF(is_pure_nnn=1,0,property_tax_annual+insurance_annual))) / 0.06 | C7: =(7500*(1+rent_annual_escalator)^(hold_period_years-1)*12 - (7500*(1+rent_annual_escalator)^(hold_period_years-1)*12*mgmt_fee_pct_of_rent + rm_annual + misc_annual + IF(is_pure_nnn=1,0,property_tax_annual+insurance_annual))) / 0.065 | D7: =(7500*(1+rent_annual_escalator)^(hold_period_years-1)*12 - (7500*(1+rent_annual_escalator)^(hold_period_years-1)*12*mgmt_fee_pct_of_rent + rm_annual + misc_annual + IF(is_pure_nnn=1,0,property_tax_annual+insurance_annual))) / 0.07 | E7: =(7500*(1+rent_annual_escalator)^(hold_period_years-1)*12 - (7500*(1+rent_annual_escalator)^(hold_period_years-1)*12*mgmt_fee_pct_of_rent + rm_annual + misc_annual + IF(is_pure_nnn=1,0,property_tax_annual+insurance_annual))) / 0.075 | F7: =(7500*(1+rent_annual_escalator)^(hold_period_years-1)*12 - (7500*(1+rent_annual_escalator)^(hold_period_years-1)*12*mgmt_fee_pct_of_rent + rm_annual + misc_annual + IF(is_pure_nnn=1,0,property_tax_annual+insurance_annual))) / 0.08 | G7: =(7500*(1+rent_annual_escalator)^(hold_period_years-1)*12 - (7500*(1+rent_annual_escalator)^(hold_period_years-1)*12*mgmt_fee_pct_of_rent + rm_annual + misc_annual + IF(is_pure_nnn=1,0,property_tax_annual+insurance_annual))) / 0.085 | H7: =(7500*(1+rent_annual_escalator)^(hold_period_years-1)*12 - (7500*(1+rent_annual_escalator)^(hold_period_years-1)*12*mgmt_fee_pct_of_rent + rm_annual + misc_annual + IF(is_pure_nnn=1,0,property_tax_annual+insurance_annual))) / 0.09 | I7: =(7500*(1+rent_annual_escalator)^(hold_period_years-1)*12 - (7500*(1+rent_annual_escalator)^(hold_period_years-1)*12*mgmt_fee_pct_of_rent + rm_annual + misc_annual + IF(is_pure_nnn=1,0,property_tax_annual+insurance_annual))) / 0.095 | J7: =(7500*(1+rent_annual_escalator)^(hold_period_years-1)*12 - (7500*(1+rent_annual_escalator)^(hold_period_years-1)*12*mgmt_fee_pct_of_rent + rm_annual + misc_annual + IF(is_pure_nnn=1,0,property_tax_annual+insurance_annual))) / 0.1
A8: 8000 | B8: =(8000*(1+rent_annual_escalator)^(hold_period_years-1)*12 - (8000*(1+rent_annual_escalator)^(hold_period_years-1)*12*mgmt_fee_pct_of_rent + rm_annual + misc_annual + IF(is_pure_nnn=1,0,property_tax_annual+insurance_annual))) / 0.06 | C8: =(8000*(1+rent_annual_escalator)^(hold_period_years-1)*12 - (8000*(1+rent_annual_escalator)^(hold_period_years-1)*12*mgmt_fee_pct_of_rent + rm_annual + misc_annual + IF(is_pure_nnn=1,0,property_tax_annual+insurance_annual))) / 0.065 | D8: =(8000*(1+rent_annual_escalator)^(hold_period_years-1)*12 - (8000*(1+rent_annual_escalator)^(hold_period_years-1)*12*mgmt_fee_pct_of_rent + rm_annual + misc_annual + IF(is_pure_nnn=1,0,property_tax_annual+insurance_annual))) / 0.07 | E8: =(8000*(1+rent_annual_escalator)^(hold_period_years-1)*12 - (8000*(1+rent_annual_escalator)^(hold_period_years-1)*12*mgmt_fee_pct_of_rent + rm_annual + misc_annual + IF(is_pure_nnn=1,0,property_tax_annual+insurance_annual))) / 0.075 | F8: =(8000*(1+rent_annual_escalator)^(hold_period_years-1)*12 - (8000*(1+rent_annual_escalator)^(hold_period_years-1)*12*mgmt_fee_pct_of_rent + rm_annual + misc_annual + IF(is_pure_nnn=1,0,property_tax_annual+insurance_annual))) / 0.08 | G8: =(8000*(1+rent_annual_escalator)^(hold_period_years-1)*12 - (8000*(1+rent_annual_escalator)^(hold_period_years-1)*12*mgmt_fee_pct_of_rent + rm_annual + misc_annual + IF(is_pure_nnn=1,0,property_tax_annual+insurance_annual))) / 0.085 | H8: =(8000*(1+rent_annual_escalator)^(hold_period_years-1)*12 - (8000*(1+rent_annual_escalator)^(hold_period_years-1)*12*mgmt_fee_pct_of_rent + rm_annual + misc_annual + IF(is_pure_nnn=1,0,property_tax_annual+insurance_annual))) / 0.09 | I8: =(8000*(1+rent_annual_escalator)^(hold_period_years-1)*12 - (8000*(1+rent_annual_escalator)^(hold_period_years-1)*12*mgmt_fee_pct_of_rent + rm_annual + misc_annual + IF(is_pure_nnn=1,0,property_tax_annual+insurance_annual))) / 0.095 | J8: =(8000*(1+rent_annual_escalator)^(hold_period_years-1)*12 - (8000*(1+rent_annual_escalator)^(hold_period_years-1)*12*mgmt_fee_pct_of_rent + rm_annual + misc_annual + IF(is_pure_nnn=1,0,property_tax_annual+insurance_annual))) / 0.1
A9: 8500 | B9: =(8500*(1+rent_annual_escalator)^(hold_period_years-1)*12 - (8500*(1+rent_annual_escalator)^(hold_period_years-1)*12*mgmt_fee_pct_of_rent + rm_annual + misc_annual + IF(is_pure_nnn=1,0,property_tax_annual+insurance_annual))) / 0.06 | C9: =(8500*(1+rent_annual_escalator)^(hold_period_years-1)*12 - (8500*(1+rent_annual_escalator)^(hold_period_years-1)*12*mgmt_fee_pct_of_rent + rm_annual + misc_annual + IF(is_pure_nnn=1,0,property_tax_annual+insurance_annual))) / 0.065 | D9: =(8500*(1+rent_annual_escalator)^(hold_period_years-1)*12 - (8500*(1+rent_annual_escalator)^(hold_period_years-1)*12*mgmt_fee_pct_of_rent + rm_annual + misc_annual + IF(is_pure_nnn=1,0,property_tax_annual+insurance_annual))) / 0.07 | E9: =(8500*(1+rent_annual_escalator)^(hold_period_years-1)*12 - (8500*(1+rent_annual_escalator)^(hold_period_years-1)*12*mgmt_fee_pct_of_rent + rm_annual + misc_annual + IF(is_pure_nnn=1,0,property_tax_annual+insurance_annual))) / 0.075 | F9: =(8500*(1+rent_annual_escalator)^(hold_period_years-1)*12 - (8500*(1+rent_annual_escalator)^(hold_period_years-1)*12*mgmt_fee_pct_of_rent + rm_annual + misc_annual + IF(is_pure_nnn=1,0,property_tax_annual+insurance_annual))) / 0.08 | G9: =(8500*(1+rent_annual_escalator)^(hold_period_years-1)*12 - (8500*(1+rent_annual_escalator)^(hold_period_years-1)*12*mgmt_fee_pct_of_rent + rm_annual + misc_annual + IF(is_pure_nnn=1,0,property_tax_annual+insurance_annual))) / 0.085 | H9: =(8500*(1+rent_annual_escalator)^(hold_period_years-1)*12 - (8500*(1+rent_annual_escalator)^(hold_period_years-1)*12*mgmt_fee_pct_of_rent + rm_annual + misc_annual + IF(is_pure_nnn=1,0,property_tax_annual+insurance_annual))) / 0.09 | I9: =(8500*(1+rent_annual_escalator)^(hold_period_years-1)*12 - (8500*(1+rent_annual_escalator)^(hold_period_years-1)*12*mgmt_fee_pct_of_rent + rm_annual + misc_annual + IF(is_pure_nnn=1,0,property_tax_annual+insurance_annual))) / 0.095 | J9: =(8500*(1+rent_annual_escalator)^(hold_period_years-1)*12 - (8500*(1+rent_annual_escalator)^(hold_period_years-1)*12*mgmt_fee_pct_of_rent + rm_annual + misc_annual + IF(is_pure_nnn=1,0,property_tax_annual+insurance_annual))) / 0.1
A10: 9000 | B10: =(9000*(1+rent_annual_escalator)^(hold_period_years-1)*12 - (9000*(1+rent_annual_escalator)^(hold_period_years-1)*12*mgmt_fee_pct_of_rent + rm_annual + misc_annual + IF(is_pure_nnn=1,0,property_tax_annual+insurance_annual))) / 0.06 | C10: =(9000*(1+rent_annual_escalator)^(hold_period_years-1)*12 - (9000*(1+rent_annual_escalator)^(hold_period_years-1)*12*mgmt_fee_pct_of_rent + rm_annual + misc_annual + IF(is_pure_nnn=1,0,property_tax_annual+insurance_annual))) / 0.065 | D10: =(9000*(1+rent_annual_escalator)^(hold_period_years-1)*12 - (9000*(1+rent_annual_escalator)^(hold_period_years-1)*12*mgmt_fee_pct_of_rent + rm_annual + misc_annual + IF(is_pure_nnn=1,0,property_tax_annual+insurance_annual))) / 0.07 | E10: =(9000*(1+rent_annual_escalator)^(hold_period_years-1)*12 - (9000*(1+rent_annual_escalator)^(hold_period_years-1)*12*mgmt_fee_pct_of_rent + rm_annual + misc_annual + IF(is_pure_nnn=1,0,property_tax_annual+insurance_annual))) / 0.075 | F10: =(9000*(1+rent_annual_escalator)^(hold_period_years-1)*12 - (9000*(1+rent_annual_escalator)^(hold_period_years-1)*12*mgmt_fee_pct_of_rent + rm_annual + misc_annual + IF(is_pure_nnn=1,0,property_tax_annual+insurance_annual))) / 0.08 | G10: =(9000*(1+rent_annual_escalator)^(hold_period_years-1)*12 - (9000*(1+rent_annual_escalator)^(hold_period_years-1)*12*mgmt_fee_pct_of_rent + rm_annual + misc_annual + IF(is_pure_nnn=1,0,property_tax_annual+insurance_annual))) / 0.085 | H10: =(9000*(1+rent_annual_escalator)^(hold_period_years-1)*12 - (9000*(1+rent_annual_escalator)^(hold_period_years-1)*12*mgmt_fee_pct_of_rent + rm_annual + misc_annual + IF(is_pure_nnn=1,0,property_tax_annual+insurance_annual))) / 0.09 | I10: =(9000*(1+rent_annual_escalator)^(hold_period_years-1)*12 - (9000*(1+rent_annual_escalator)^(hold_period_years-1)*12*mgmt_fee_pct_of_rent + rm_annual + misc_annual + IF(is_pure_nnn=1,0,property_tax_annual+insurance_annual))) / 0.095 | J10: =(9000*(1+rent_annual_escalator)^(hold_period_years-1)*12 - (9000*(1+rent_annual_escalator)^(hold_period_years-1)*12*mgmt_fee_pct_of_rent + rm_annual + misc_annual + IF(is_pure_nnn=1,0,property_tax_annual+insurance_annual))) / 0.1
A11: 9500 | B11: =(9500*(1+rent_annual_escalator)^(hold_period_years-1)*12 - (9500*(1+rent_annual_escalator)^(hold_period_years-1)*12*mgmt_fee_pct_of_rent + rm_annual + misc_annual + IF(is_pure_nnn=1,0,property_tax_annual+insurance_annual))) / 0.06 | C11: =(9500*(1+rent_annual_escalator)^(hold_period_years-1)*12 - (9500*(1+rent_annual_escalator)^(hold_period_years-1)*12*mgmt_fee_pct_of_rent + rm_annual + misc_annual + IF(is_pure_nnn=1,0,property_tax_annual+insurance_annual))) / 0.065 | D11: =(9500*(1+rent_annual_escalator)^(hold_period_years-1)*12 - (9500*(1+rent_annual_escalator)^(hold_period_years-1)*12*mgmt_fee_pct_of_rent + rm_annual + misc_annual + IF(is_pure_nnn=1,0,property_tax_annual+insurance_annual))) / 0.07 | E11: =(9500*(1+rent_annual_escalator)^(hold_period_years-1)*12 - (9500*(1+rent_annual_escalator)^(hold_period_years-1)*12*mgmt_fee_pct_of_rent + rm_annual + misc_annual + IF(is_pure_nnn=1,0,property_tax_annual+insurance_annual))) / 0.075 | F11: =(9500*(1+rent_annual_escalator)^(hold_period_years-1)*12 - (9500*(1+rent_annual_escalator)^(hold_period_years-1)*12*mgmt_fee_pct_of_rent + rm_annual + misc_annual + IF(is_pure_nnn=1,0,property_tax_annual+insurance_annual))) / 0.08 | G11: =(9500*(1+rent_annual_escalator)^(hold_period_years-1)*12 - (9500*(1+rent_annual_escalator)^(hold_period_years-1)*12*mgmt_fee_pct_of_rent + rm_annual + misc_annual + IF(is_pure_nnn=1,0,property_tax_annual+insurance_annual))) / 0.085 | H11: =(9500*(1+rent_annual_escalator)^(hold_period_years-1)*12 - (9500*(1+rent_annual_escalator)^(hold_period_years-1)*12*mgmt_fee_pct_of_rent + rm_annual + misc_annual + IF(is_pure_nnn=1,0,property_tax_annual+insurance_annual))) / 0.09 | I11: =(9500*(1+rent_annual_escalator)^(hold_period_years-1)*12 - (9500*(1+rent_annual_escalator)^(hold_period_years-1)*12*mgmt_fee_pct_of_rent + rm_annual + misc_annual + IF(is_pure_nnn=1,0,property_tax_annual+insurance_annual))) / 0.095 | J11: =(9500*(1+rent_annual_escalator)^(hold_period_years-1)*12 - (9500*(1+rent_annual_escalator)^(hold_period_years-1)*12*mgmt_fee_pct_of_rent + rm_annual + misc_annual + IF(is_pure_nnn=1,0,property_tax_annual+insurance_annual))) / 0.1
A12: 10000 | B12: =(10000*(1+rent_annual_escalator)^(hold_period_years-1)*12 - (10000*(1+rent_annual_escalator)^(hold_period_years-1)*12*mgmt_fee_pct_of_rent + rm_annual + misc_annual + IF(is_pure_nnn=1,0,property_tax_annual+insurance_annual))) / 0.06 | C12: =(10000*(1+rent_annual_escalator)^(hold_period_years-1)*12 - (10000*(1+rent_annual_escalator)^(hold_period_years-1)*12*mgmt_fee_pct_of_rent + rm_annual + misc_annual + IF(is_pure_nnn=1,0,property_tax_annual+insurance_annual))) / 0.065 | D12: =(10000*(1+rent_annual_escalator)^(hold_period_years-1)*12 - (10000*(1+rent_annual_escalator)^(hold_period_years-1)*12*mgmt_fee_pct_of_rent + rm_annual + misc_annual + IF(is_pure_nnn=1,0,property_tax_annual+insurance_annual))) / 0.07 | E12: =(10000*(1+rent_annual_escalator)^(hold_period_years-1)*12 - (10000*(1+rent_annual_escalator)^(hold_period_years-1)*12*mgmt_fee_pct_of_rent + rm_annual + misc_annual + IF(is_pure_nnn=1,0,property_tax_annual+insurance_annual))) / 0.075 | F12: =(10000*(1+rent_annual_escalator)^(hold_period_years-1)*12 - (10000*(1+rent_annual_escalator)^(hold_period_years-1)*12*mgmt_fee_pct_of_rent + rm_annual + misc_annual + IF(is_pure_nnn=1,0,property_tax_annual+insurance_annual))) / 0.08 | G12: =(10000*(1+rent_annual_escalator)^(hold_period_years-1)*12 - (10000*(1+rent_annual_escalator)^(hold_period_years-1)*12*mgmt_fee_pct_of_rent + rm_annual + misc_annual + IF(is_pure_nnn=1,0,property_tax_annual+insurance_annual))) / 0.085 | H12: =(10000*(1+rent_annual_escalator)^(hold_period_years-1)*12 - (10000*(1+rent_annual_escalator)^(hold_period_years-1)*12*mgmt_fee_pct_of_rent + rm_annual + misc_annual + IF(is_pure_nnn=1,0,property_tax_annual+insurance_annual))) / 0.09 | I12: =(10000*(1+rent_annual_escalator)^(hold_period_years-1)*12 - (10000*(1+rent_annual_escalator)^(hold_period_years-1)*12*mgmt_fee_pct_of_rent + rm_annual + misc_annual + IF(is_pure_nnn=1,0,property_tax_annual+insurance_annual))) / 0.095 | J12: =(10000*(1+rent_annual_escalator)^(hold_period_years-1)*12 - (10000*(1+rent_annual_escalator)^(hold_period_years-1)*12*mgmt_fee_pct_of_rent + rm_annual + misc_annual + IF(is_pure_nnn=1,0,property_tax_annual+insurance_annual))) / 0.1
A13: 10500 | B13: =(10500*(1+rent_annual_escalator)^(hold_period_years-1)*12 - (10500*(1+rent_annual_escalator)^(hold_period_years-1)*12*mgmt_fee_pct_of_rent + rm_annual + misc_annual + IF(is_pure_nnn=1,0,property_tax_annual+insurance_annual))) / 0.06 | C13: =(10500*(1+rent_annual_escalator)^(hold_period_years-1)*12 - (10500*(1+rent_annual_escalator)^(hold_period_years-1)*12*mgmt_fee_pct_of_rent + rm_annual + misc_annual + IF(is_pure_nnn=1,0,property_tax_annual+insurance_annual))) / 0.065 | D13: =(10500*(1+rent_annual_escalator)^(hold_period_years-1)*12 - (10500*(1+rent_annual_escalator)^(hold_period_years-1)*12*mgmt_fee_pct_of_rent + rm_annual + misc_annual + IF(is_pure_nnn=1,0,property_tax_annual+insurance_annual))) / 0.07 | E13: =(10500*(1+rent_annual_escalator)^(hold_period_years-1)*12 - (10500*(1+rent_annual_escalator)^(hold_period_years-1)*12*mgmt_fee_pct_of_rent + rm_annual + misc_annual + IF(is_pure_nnn=1,0,property_tax_annual+insurance_annual))) / 0.075 | F13: =(10500*(1+rent_annual_escalator)^(hold_period_years-1)*12 - (10500*(1+rent_annual_escalator)^(hold_period_years-1)*12*mgmt_fee_pct_of_rent + rm_annual + misc_annual + IF(is_pure_nnn=1,0,property_tax_annual+insurance_annual))) / 0.08 | G13: =(10500*(1+rent_annual_escalator)^(hold_period_years-1)*12 - (10500*(1+rent_annual_escalator)^(hold_period_years-1)*12*mgmt_fee_pct_of_rent + rm_annual + misc_annual + IF(is_pure_nnn=1,0,property_tax_annual+insurance_annual))) / 0.085 | H13: =(10500*(1+rent_annual_escalator)^(hold_period_years-1)*12 - (10500*(1+rent_annual_escalator)^(hold_period_years-1)*12*mgmt_fee_pct_of_rent + rm_annual + misc_annual + IF(is_pure_nnn=1,0,property_tax_annual+insurance_annual))) / 0.09 | I13: =(10500*(1+rent_annual_escalator)^(hold_period_years-1)*12 - (10500*(1+rent_annual_escalator)^(hold_period_years-1)*12*mgmt_fee_pct_of_rent + rm_annual + misc_annual + IF(is_pure_nnn=1,0,property_tax_annual+insurance_annual))) / 0.095 | J13: =(10500*(1+rent_annual_escalator)^(hold_period_years-1)*12 - (10500*(1+rent_annual_escalator)^(hold_period_years-1)*12*mgmt_fee_pct_of_rent + rm_annual + misc_annual + IF(is_pure_nnn=1,0,property_tax_annual+insurance_annual))) / 0.1
A14: 11000 | B14: =(11000*(1+rent_annual_escalator)^(hold_period_years-1)*12 - (11000*(1+rent_annual_escalator)^(hold_period_years-1)*12*mgmt_fee_pct_of_rent + rm_annual + misc_annual + IF(is_pure_nnn=1,0,property_tax_annual+insurance_annual))) / 0.06 | C14: =(11000*(1+rent_annual_escalator)^(hold_period_years-1)*12 - (11000*(1+rent_annual_escalator)^(hold_period_years-1)*12*mgmt_fee_pct_of_rent + rm_annual + misc_annual + IF(is_pure_nnn=1,0,property_tax_annual+insurance_annual))) / 0.065 | D14: =(11000*(1+rent_annual_escalator)^(hold_period_years-1)*12 - (11000*(1+rent_annual_escalator)^(hold_period_years-1)*12*mgmt_fee_pct_of_rent + rm_annual + misc_annual + IF(is_pure_nnn=1,0,property_tax_annual+insurance_annual))) / 0.07 | E14: =(11000*(1+rent_annual_escalator)^(hold_period_years-1)*12 - (11000*(1+rent_annual_escalator)^(hold_period_years-1)*12*mgmt_fee_pct_of_rent + rm_annual + misc_annual + IF(is_pure_nnn=1,0,property_tax_annual+insurance_annual))) / 0.075 | F14: =(11000*(1+rent_annual_escalator)^(hold_period_years-1)*12 - (11000*(1+rent_annual_escalator)^(hold_period_years-1)*12*mgmt_fee_pct_of_rent + rm_annual + misc_annual + IF(is_pure_nnn=1,0,property_tax_annual+insurance_annual))) / 0.08 | G14: =(11000*(1+rent_annual_escalator)^(hold_period_years-1)*12 - (11000*(1+rent_annual_escalator)^(hold_period_years-1)*12*mgmt_fee_pct_of_rent + rm_annual + misc_annual + IF(is_pure_nnn=1,0,property_tax_annual+insurance_annual))) / 0.085 | H14: =(11000*(1+rent_annual_escalator)^(hold_period_years-1)*12 - (11000*(1+rent_annual_escalator)^(hold_period_years-1)*12*mgmt_fee_pct_of_rent + rm_annual + misc_annual + IF(is_pure_nnn=1,0,property_tax_annual+insurance_annual))) / 0.09 | I14: =(11000*(1+rent_annual_escalator)^(hold_period_years-1)*12 - (11000*(1+rent_annual_escalator)^(hold_period_years-1)*12*mgmt_fee_pct_of_rent + rm_annual + misc_annual + IF(is_pure_nnn=1,0,property_tax_annual+insurance_annual))) / 0.095 | J14: =(11000*(1+rent_annual_escalator)^(hold_period_years-1)*12 - (11000*(1+rent_annual_escalator)^(hold_period_years-1)*12*mgmt_fee_pct_of_rent + rm_annual + misc_annual + IF(is_pure_nnn=1,0,property_tax_annual+insurance_annual))) / 0.1
A15: 11500 | B15: =(11500*(1+rent_annual_escalator)^(hold_period_years-1)*12 - (11500*(1+rent_annual_escalator)^(hold_period_years-1)*12*mgmt_fee_pct_of_rent + rm_annual + misc_annual + IF(is_pure_nnn=1,0,property_tax_annual+insurance_annual))) / 0.06 | C15: =(11500*(1+rent_annual_escalator)^(hold_period_years-1)*12 - (11500*(1+rent_annual_escalator)^(hold_period_years-1)*12*mgmt_fee_pct_of_rent + rm_annual + misc_annual + IF(is_pure_nnn=1,0,property_tax_annual+insurance_annual))) / 0.065 | D15: =(11500*(1+rent_annual_escalator)^(hold_period_years-1)*12 - (11500*(1+rent_annual_escalator)^(hold_period_years-1)*12*mgmt_fee_pct_of_rent + rm_annual + misc_annual + IF(is_pure_nnn=1,0,property_tax_annual+insurance_annual))) / 0.07 | E15: =(11500*(1+rent_annual_escalator)^(hold_period_years-1)*12 - (11500*(1+rent_annual_escalator)^(hold_period_years-1)*12*mgmt_fee_pct_of_rent + rm_annual + misc_annual + IF(is_pure_nnn=1,0,property_tax_annual+insurance_annual))) / 0.075 | F15: =(11500*(1+rent_annual_escalator)^(hold_period_years-1)*12 - (11500*(1+rent_annual_escalator)^(hold_period_years-1)*12*mgmt_fee_pct_of_rent + rm_annual + misc_annual + IF(is_pure_nnn=1,0,property_tax_annual+insurance_annual))) / 0.08 | G15: =(11500*(1+rent_annual_escalator)^(hold_period_years-1)*12 - (11500*(1+rent_annual_escalator)^(hold_period_years-1)*12*mgmt_fee_pct_of_rent + rm_annual + misc_annual + IF(is_pure_nnn=1,0,property_tax_annual+insurance_annual))) / 0.085 | H15: =(11500*(1+rent_annual_escalator)^(hold_period_years-1)*12 - (11500*(1+rent_annual_escalator)^(hold_period_years-1)*12*mgmt_fee_pct_of_rent + rm_annual + misc_annual + IF(is_pure_nnn=1,0,property_tax_annual+insurance_annual))) / 0.09 | I15: =(11500*(1+rent_annual_escalator)^(hold_period_years-1)*12 - (11500*(1+rent_annual_escalator)^(hold_period_years-1)*12*mgmt_fee_pct_of_rent + rm_annual + misc_annual + IF(is_pure_nnn=1,0,property_tax_annual+insurance_annual))) / 0.095 | J15: =(11500*(1+rent_annual_escalator)^(hold_period_years-1)*12 - (11500*(1+rent_annual_escalator)^(hold_period_years-1)*12*mgmt_fee_pct_of_rent + rm_annual + misc_annual + IF(is_pure_nnn=1,0,property_tax_annual+insurance_annual))) / 0.1
A16: 12000 | B16: =(12000*(1+rent_annual_escalator)^(hold_period_years-1)*12 - (12000*(1+rent_annual_escalator)^(hold_period_years-1)*12*mgmt_fee_pct_of_rent + rm_annual + misc_annual + IF(is_pure_nnn=1,0,property_tax_annual+insurance_annual))) / 0.06 | C16: =(12000*(1+rent_annual_escalator)^(hold_period_years-1)*12 - (12000*(1+rent_annual_escalator)^(hold_period_years-1)*12*mgmt_fee_pct_of_rent + rm_annual + misc_annual + IF(is_pure_nnn=1,0,property_tax_annual+insurance_annual))) / 0.065 | D16: =(12000*(1+rent_annual_escalator)^(hold_period_years-1)*12 - (12000*(1+rent_annual_escalator)^(hold_period_years-1)*12*mgmt_fee_pct_of_rent + rm_annual + misc_annual + IF(is_pure_nnn=1,0,property_tax_annual+insurance_annual))) / 0.07 | E16: =(12000*(1+rent_annual_escalator)^(hold_period_years-1)*12 - (12000*(1+rent_annual_escalator)^(hold_period_years-1)*12*mgmt_fee_pct_of_rent + rm_annual + misc_annual + IF(is_pure_nnn=1,0,property_tax_annual+insurance_annual))) / 0.075 | F16: =(12000*(1+rent_annual_escalator)^(hold_period_years-1)*12 - (12000*(1+rent_annual_escalator)^(hold_period_years-1)*12*mgmt_fee_pct_of_rent + rm_annual + misc_annual + IF(is_pure_nnn=1,0,property_tax_annual+insurance_annual))) / 0.08 | G16: =(12000*(1+rent_annual_escalator)^(hold_period_years-1)*12 - (12000*(1+rent_annual_escalator)^(hold_period_years-1)*12*mgmt_fee_pct_of_rent + rm_annual + misc_annual + IF(is_pure_nnn=1,0,property_tax_annual+insurance_annual))) / 0.085 | H16: =(12000*(1+rent_annual_escalator)^(hold_period_years-1)*12 - (12000*(1+rent_annual_escalator)^(hold_period_years-1)*12*mgmt_fee_pct_of_rent + rm_annual + misc_annual + IF(is_pure_nnn=1,0,property_tax_annual+insurance_annual))) / 0.09 | I16: =(12000*(1+rent_annual_escalator)^(hold_period_years-1)*12 - (12000*(1+rent_annual_escalator)^(hold_period_years-1)*12*mgmt_fee_pct_of_rent + rm_annual + misc_annual + IF(is_pure_nnn=1,0,property_tax_annual+insurance_annual))) / 0.095 | J16: =(12000*(1+rent_annual_escalator)^(hold_period_years-1)*12 - (12000*(1+rent_annual_escalator)^(hold_period_years-1)*12*mgmt_fee_pct_of_rent + rm_annual + misc_annual + IF(is_pure_nnn=1,0,property_tax_annual+insurance_annual))) / 0.1
A17: 12500 | B17: =(12500*(1+rent_annual_escalator)^(hold_period_years-1)*12 - (12500*(1+rent_annual_escalator)^(hold_period_years-1)*12*mgmt_fee_pct_of_rent + rm_annual + misc_annual + IF(is_pure_nnn=1,0,property_tax_annual+insurance_annual))) / 0.06 | C17: =(12500*(1+rent_annual_escalator)^(hold_period_years-1)*12 - (12500*(1+rent_annual_escalator)^(hold_period_years-1)*12*mgmt_fee_pct_of_rent + rm_annual + misc_annual + IF(is_pure_nnn=1,0,property_tax_annual+insurance_annual))) / 0.065 | D17: =(12500*(1+rent_annual_escalator)^(hold_period_years-1)*12 - (12500*(1+rent_annual_escalator)^(hold_period_years-1)*12*mgmt_fee_pct_of_rent + rm_annual + misc_annual + IF(is_pure_nnn=1,0,property_tax_annual+insurance_annual))) / 0.07 | E17: =(12500*(1+rent_annual_escalator)^(hold_period_years-1)*12 - (12500*(1+rent_annual_escalator)^(hold_period_years-1)*12*mgmt_fee_pct_of_rent + rm_annual + misc_annual + IF(is_pure_nnn=1,0,property_tax_annual+insurance_annual))) / 0.075 | F17: =(12500*(1+rent_annual_escalator)^(hold_period_years-1)*12 - (12500*(1+rent_annual_escalator)^(hold_period_years-1)*12*mgmt_fee_pct_of_rent + rm_annual + misc_annual + IF(is_pure_nnn=1,0,property_tax_annual+insurance_annual))) / 0.08 | G17: =(12500*(1+rent_annual_escalator)^(hold_period_years-1)*12 - (12500*(1+rent_annual_escalator)^(hold_period_years-1)*12*mgmt_fee_pct_of_rent + rm_annual + misc_annual + IF(is_pure_nnn=1,0,property_tax_annual+insurance_annual))) / 0.085 | H17: =(12500*(1+rent_annual_escalator)^(hold_period_years-1)*12 - (12500*(1+rent_annual_escalator)^(hold_period_years-1)*12*mgmt_fee_pct_of_rent + rm_annual + misc_annual + IF(is_pure_nnn=1,0,property_tax_annual+insurance_annual))) / 0.09 | I17: =(12500*(1+rent_annual_escalator)^(hold_period_years-1)*12 - (12500*(1+rent_annual_escalator)^(hold_period_years-1)*12*mgmt_fee_pct_of_rent + rm_annual + misc_annual + IF(is_pure_nnn=1,0,property_tax_annual+insurance_annual))) / 0.095 | J17: =(12500*(1+rent_annual_escalator)^(hold_period_years-1)*12 - (12500*(1+rent_annual_escalator)^(hold_period_years-1)*12*mgmt_fee_pct_of_rent + rm_annual + misc_annual + IF(is_pure_nnn=1,0,property_tax_annual+insurance_annual))) / 0.1
A18: 13000 | B18: =(13000*(1+rent_annual_escalator)^(hold_period_years-1)*12 - (13000*(1+rent_annual_escalator)^(hold_period_years-1)*12*mgmt_fee_pct_of_rent + rm_annual + misc_annual + IF(is_pure_nnn=1,0,property_tax_annual+insurance_annual))) / 0.06 | C18: =(13000*(1+rent_annual_escalator)^(hold_period_years-1)*12 - (13000*(1+rent_annual_escalator)^(hold_period_years-1)*12*mgmt_fee_pct_of_rent + rm_annual + misc_annual + IF(is_pure_nnn=1,0,property_tax_annual+insurance_annual))) / 0.065 | D18: =(13000*(1+rent_annual_escalator)^(hold_period_years-1)*12 - (13000*(1+rent_annual_escalator)^(hold_period_years-1)*12*mgmt_fee_pct_of_rent + rm_annual + misc_annual + IF(is_pure_nnn=1,0,property_tax_annual+insurance_annual))) / 0.07 | E18: =(13000*(1+rent_annual_escalator)^(hold_period_years-1)*12 - (13000*(1+rent_annual_escalator)^(hold_period_years-1)*12*mgmt_fee_pct_of_rent + rm_annual + misc_annual + IF(is_pure_nnn=1,0,property_tax_annual+insurance_annual))) / 0.075 | F18: =(13000*(1+rent_annual_escalator)^(hold_period_years-1)*12 - (13000*(1+rent_annual_escalator)^(hold_period_years-1)*12*mgmt_fee_pct_of_rent + rm_annual + misc_annual + IF(is_pure_nnn=1,0,property_tax_annual+insurance_annual))) / 0.08 | G18: =(13000*(1+rent_annual_escalator)^(hold_period_years-1)*12 - (13000*(1+rent_annual_escalator)^(hold_period_years-1)*12*mgmt_fee_pct_of_rent + rm_annual + misc_annual + IF(is_pure_nnn=1,0,property_tax_annual+insurance_annual))) / 0.085 | H18: =(13000*(1+rent_annual_escalator)^(hold_period_years-1)*12 - (13000*(1+rent_annual_escalator)^(hold_period_years-1)*12*mgmt_fee_pct_of_rent + rm_annual + misc_annual + IF(is_pure_nnn=1,0,property_tax_annual+insurance_annual))) / 0.09 | I18: =(13000*(1+rent_annual_escalator)^(hold_period_years-1)*12 - (13000*(1+rent_annual_escalator)^(hold_period_years-1)*12*mgmt_fee_pct_of_rent + rm_annual + misc_annual + IF(is_pure_nnn=1,0,property_tax_annual+insurance_annual))) / 0.095 | J18: =(13000*(1+rent_annual_escalator)^(hold_period_years-1)*12 - (13000*(1+rent_annual_escalator)^(hold_period_years-1)*12*mgmt_fee_pct_of_rent + rm_annual + misc_annual + IF(is_pure_nnn=1,0,property_tax_annual+insurance_annual))) / 0.1
A21: TABLE 2 — Year 1 cash flow: rent × loan rate
A23: Yr1 Rent ↓ / Loan Rate → | B23: 0.05 | C23: 0.055 | D23: 0.06 | E23: 0.065 | F23: 0.07 | G23: 0.075 | H23: 0.08 | I23: 0.085 | J23: 0.09 | K23: 0.095 | L23: 0.1
A24: 7000 | B24: =(7000*12 - (7000*12*mgmt_fee_pct_of_rent + rm_annual + misc_annual + IF(is_pure_nnn=1,0,property_tax_annual+insurance_annual))) - (-PMT(0.05/12,loan_amortization_years*12,purchase_price*loan_to_value)*12) | C24: =(7000*12 - (7000*12*mgmt_fee_pct_of_rent + rm_annual + misc_annual + IF(is_pure_nnn=1,0,property_tax_annual+insurance_annual))) - (-PMT(0.055/12,loan_amortization_years*12,purchase_price*loan_to_value)*12) | D24: =(7000*12 - (7000*12*mgmt_fee_pct_of_rent + rm_annual + misc_annual + IF(is_pure_nnn=1,0,property_tax_annual+insurance_annual))) - (-PMT(0.06/12,loan_amortization_years*12,purchase_price*loan_to_value)*12) | E24: =(7000*12 - (7000*12*mgmt_fee_pct_of_rent + rm_annual + misc_annual + IF(is_pure_nnn=1,0,property_tax_annual+insurance_annual))) - (-PMT(0.065/12,loan_amortization_years*12,purchase_price*loan_to_value)*12) | F24: =(7000*12 - (7000*12*mgmt_fee_pct_of_rent + rm_annual + misc_annual + IF(is_pure_nnn=1,0,property_tax_annual+insurance_annual))) - (-PMT(0.07/12,loan_amortization_years*12,purchase_price*loan_to_value)*12) | G24: =(7000*12 - (7000*12*mgmt_fee_pct_of_rent + rm_annual + misc_annual + IF(is_pure_nnn=1,0,property_tax_annual+insurance_annual))) - (-PMT(0.075/12,loan_amortization_years*12,purchase_price*loan_to_value)*12) | H24: =(7000*12 - (7000*12*mgmt_fee_pct_of_rent + rm_annual + misc_annual + IF(is_pure_nnn=1,0,property_tax_annual+insurance_annual))) - (-PMT(0.08/12,loan_amortization_years*12,purchase_price*loan_to_value)*12) | I24: =(7000*12 - (7000*12*mgmt_fee_pct_of_rent + rm_annual + misc_annual + IF(is_pure_nnn=1,0,property_tax_annual+insurance_annual))) - (-PMT(0.085/12,loan_amortization_years*12,purchase_price*loan_to_value)*12) | J24: =(7000*12 - (7000*12*mgmt_fee_pct_of_rent + rm_annual + misc_annual + IF(is_pure_nnn=1,0,property_tax_annual+insurance_annual))) - (-PMT(0.09/12,loan_amortization_years*12,purchase_price*loan_to_value)*12) | K24: =(7000*12 - (7000*12*mgmt_fee_pct_of_rent + rm_annual + misc_annual + IF(is_pure_nnn=1,0,property_tax_annual+insurance_annual))) - (-PMT(0.095/12,loan_amortization_years*12,purchase_price*loan_to_value)*12) | L24: =(7000*12 - (7000*12*mgmt_fee_pct_of_rent + rm_annual + misc_annual + IF(is_pure_nnn=1,0,property_tax_annual+insurance_annual))) - (-PMT(0.1/12,loan_amortization_years*12,purchase_price*loan_to_value)*12)
A25: 7500 | B25: =(7500*12 - (7500*12*mgmt_fee_pct_of_rent + rm_annual + misc_annual + IF(is_pure_nnn=1,0,property_tax_annual+insurance_annual))) - (-PMT(0.05/12,loan_amortization_years*12,purchase_price*loan_to_value)*12) | C25: =(7500*12 - (7500*12*mgmt_fee_pct_of_rent + rm_annual + misc_annual + IF(is_pure_nnn=1,0,property_tax_annual+insurance_annual))) - (-PMT(0.055/12,loan_amortization_years*12,purchase_price*loan_to_value)*12) | D25: =(7500*12 - (7500*12*mgmt_fee_pct_of_rent + rm_annual + misc_annual + IF(is_pure_nnn=1,0,property_tax_annual+insurance_annual))) - (-PMT(0.06/12,loan_amortization_years*12,purchase_price*loan_to_value)*12) | E25: =(7500*12 - (7500*12*mgmt_fee_pct_of_rent + rm_annual + misc_annual + IF(is_pure_nnn=1,0,property_tax_annual+insurance_annual))) - (-PMT(0.065/12,loan_amortization_years*12,purchase_price*loan_to_value)*12) | F25: =(7500*12 - (7500*12*mgmt_fee_pct_of_rent + rm_annual + misc_annual + IF(is_pure_nnn=1,0,property_tax_annual+insurance_annual))) - (-PMT(0.07/12,loan_amortization_years*12,purchase_price*loan_to_value)*12) | G25: =(7500*12 - (7500*12*mgmt_fee_pct_of_rent + rm_annual + misc_annual + IF(is_pure_nnn=1,0,property_tax_annual+insurance_annual))) - (-PMT(0.075/12,loan_amortization_years*12,purchase_price*loan_to_value)*12) | H25: =(7500*12 - (7500*12*mgmt_fee_pct_of_rent + rm_annual + misc_annual + IF(is_pure_nnn=1,0,property_tax_annual+insurance_annual))) - (-PMT(0.08/12,loan_amortization_years*12,purchase_price*loan_to_value)*12) | I25: =(7500*12 - (7500*12*mgmt_fee_pct_of_rent + rm_annual + misc_annual + IF(is_pure_nnn=1,0,property_tax_annual+insurance_annual))) - (-PMT(0.085/12,loan_amortization_years*12,purchase_price*loan_to_value)*12) | J25: =(7500*12 - (7500*12*mgmt_fee_pct_of_rent + rm_annual + misc_annual + IF(is_pure_nnn=1,0,property_tax_annual+insurance_annual))) - (-PMT(0.09/12,loan_amortization_years*12,purchase_price*loan_to_value)*12) | K25: =(7500*12 - (7500*12*mgmt_fee_pct_of_rent + rm_annual + misc_annual + IF(is_pure_nnn=1,0,property_tax_annual+insurance_annual))) - (-PMT(0.095/12,loan_amortization_years*12,purchase_price*loan_to_value)*12) | L25: =(7500*12 - (7500*12*mgmt_fee_pct_of_rent + rm_annual + misc_annual + IF(is_pure_nnn=1,0,property_tax_annual+insurance_annual))) - (-PMT(0.1/12,loan_amortization_years*12,purchase_price*loan_to_value)*12)
A26: 8000 | B26: =(8000*12 - (8000*12*mgmt_fee_pct_of_rent + rm_annual + misc_annual + IF(is_pure_nnn=1,0,property_tax_annual+insurance_annual))) - (-PMT(0.05/12,loan_amortization_years*12,purchase_price*loan_to_value)*12) | C26: =(8000*12 - (8000*12*mgmt_fee_pct_of_rent + rm_annual + misc_annual + IF(is_pure_nnn=1,0,property_tax_annual+insurance_annual))) - (-PMT(0.055/12,loan_amortization_years*12,purchase_price*loan_to_value)*12) | D26: =(8000*12 - (8000*12*mgmt_fee_pct_of_rent + rm_annual + misc_annual + IF(is_pure_nnn=1,0,property_tax_annual+insurance_annual))) - (-PMT(0.06/12,loan_amortization_years*12,purchase_price*loan_to_value)*12) | E26: =(8000*12 - (8000*12*mgmt_fee_pct_of_rent + rm_annual + misc_annual + IF(is_pure_nnn=1,0,property_tax_annual+insurance_annual))) - (-PMT(0.065/12,loan_amortization_years*12,purchase_price*loan_to_value)*12) | F26: =(8000*12 - (8000*12*mgmt_fee_pct_of_rent + rm_annual + misc_annual + IF(is_pure_nnn=1,0,property_tax_annual+insurance_annual))) - (-PMT(0.07/12,loan_amortization_years*12,purchase_price*loan_to_value)*12) | G26: =(8000*12 - (8000*12*mgmt_fee_pct_of_rent + rm_annual + misc_annual + IF(is_pure_nnn=1,0,property_tax_annual+insurance_annual))) - (-PMT(0.075/12,loan_amortization_years*12,purchase_price*loan_to_value)*12) | H26: =(8000*12 - (8000*12*mgmt_fee_pct_of_rent + rm_annual + misc_annual + IF(is_pure_nnn=1,0,property_tax_annual+insurance_annual))) - (-PMT(0.08/12,loan_amortization_years*12,purchase_price*loan_to_value)*12) | I26: =(8000*12 - (8000*12*mgmt_fee_pct_of_rent + rm_annual + misc_annual + IF(is_pure_nnn=1,0,property_tax_annual+insurance_annual))) - (-PMT(0.085/12,loan_amortization_years*12,purchase_price*loan_to_value)*12) | J26: =(8000*12 - (8000*12*mgmt_fee_pct_of_rent + rm_annual + misc_annual + IF(is_pure_nnn=1,0,property_tax_annual+insurance_annual))) - (-PMT(0.09/12,loan_amortization_years*12,purchase_price*loan_to_value)*12) | K26: =(8000*12 - (8000*12*mgmt_fee_pct_of_rent + rm_annual + misc_annual + IF(is_pure_nnn=1,0,property_tax_annual+insurance_annual))) - (-PMT(0.095/12,loan_amortization_years*12,purchase_price*loan_to_value)*12) | L26: =(8000*12 - (8000*12*mgmt_fee_pct_of_rent + rm_annual + misc_annual + IF(is_pure_nnn=1,0,property_tax_annual+insurance_annual))) - (-PMT(0.1/12,loan_amortization_years*12,purchase_price*loan_to_value)*12)
A27: 8500 | B27: =(8500*12 - (8500*12*mgmt_fee_pct_of_rent + rm_annual + misc_annual + IF(is_pure_nnn=1,0,property_tax_annual+insurance_annual))) - (-PMT(0.05/12,loan_amortization_years*12,purchase_price*loan_to_value)*12) | C27: =(8500*12 - (8500*12*mgmt_fee_pct_of_rent + rm_annual + misc_annual + IF(is_pure_nnn=1,0,property_tax_annual+insurance_annual))) - (-PMT(0.055/12,loan_amortization_years*12,purchase_price*loan_to_value)*12) | D27: =(8500*12 - (8500*12*mgmt_fee_pct_of_rent + rm_annual + misc_annual + IF(is_pure_nnn=1,0,property_tax_annual+insurance_annual))) - (-PMT(0.06/12,loan_amortization_years*12,purchase_price*loan_to_value)*12) | E27: =(8500*12 - (8500*12*mgmt_fee_pct_of_rent + rm_annual + misc_annual + IF(is_pure_nnn=1,0,property_tax_annual+insurance_annual))) - (-PMT(0.065/12,loan_amortization_years*12,purchase_price*loan_to_value)*12) | F27: =(8500*12 - (8500*12*mgmt_fee_pct_of_rent + rm_annual + misc_annual + IF(is_pure_nnn=1,0,property_tax_annual+insurance_annual))) - (-PMT(0.07/12,loan_amortization_years*12,purchase_price*loan_to_value)*12) | G27: =(8500*12 - (8500*12*mgmt_fee_pct_of_rent + rm_annual + misc_annual + IF(is_pure_nnn=1,0,property_tax_annual+insurance_annual))) - (-PMT(0.075/12,loan_amortization_years*12,purchase_price*loan_to_value)*12) | H27: =(8500*12 - (8500*12*mgmt_fee_pct_of_rent + rm_annual + misc_annual + IF(is_pure_nnn=1,0,property_tax_annual+insurance_annual))) - (-PMT(0.08/12,loan_amortization_years*12,purchase_price*loan_to_value)*12) | I27: =(8500*12 - (8500*12*mgmt_fee_pct_of_rent + rm_annual + misc_annual + IF(is_pure_nnn=1,0,property_tax_annual+insurance_annual))) - (-PMT(0.085/12,loan_amortization_years*12,purchase_price*loan_to_value)*12) | J27: =(8500*12 - (8500*12*mgmt_fee_pct_of_rent + rm_annual + misc_annual + IF(is_pure_nnn=1,0,property_tax_annual+insurance_annual))) - (-PMT(0.09/12,loan_amortization_years*12,purchase_price*loan_to_value)*12) | K27: =(8500*12 - (8500*12*mgmt_fee_pct_of_rent + rm_annual + misc_annual + IF(is_pure_nnn=1,0,property_tax_annual+insurance_annual))) - (-PMT(0.095/12,loan_amortization_years*12,purchase_price*loan_to_value)*12) | L27: =(8500*12 - (8500*12*mgmt_fee_pct_of_rent + rm_annual + misc_annual + IF(is_pure_nnn=1,0,property_tax_annual+insurance_annual))) - (-PMT(0.1/12,loan_amortization_years*12,purchase_price*loan_to_value)*12)
A28: 9000 | B28: =(9000*12 - (9000*12*mgmt_fee_pct_of_rent + rm_annual + misc_annual + IF(is_pure_nnn=1,0,property_tax_annual+insurance_annual))) - (-PMT(0.05/12,loan_amortization_years*12,purchase_price*loan_to_value)*12) | C28: =(9000*12 - (9000*12*mgmt_fee_pct_of_rent + rm_annual + misc_annual + IF(is_pure_nnn=1,0,property_tax_annual+insurance_annual))) - (-PMT(0.055/12,loan_amortization_years*12,purchase_price*loan_to_value)*12) | D28: =(9000*12 - (9000*12*mgmt_fee_pct_of_rent + rm_annual + misc_annual + IF(is_pure_nnn=1,0,property_tax_annual+insurance_annual))) - (-PMT(0.06/12,loan_amortization_years*12,purchase_price*loan_to_value)*12) | E28: =(9000*12 - (9000*12*mgmt_fee_pct_of_rent + rm_annual + misc_annual + IF(is_pure_nnn=1,0,property_tax_annual+insurance_annual))) - (-PMT(0.065/12,loan_amortization_years*12,purchase_price*loan_to_value)*12) | F28: =(9000*12 - (9000*12*mgmt_fee_pct_of_rent + rm_annual + misc_annual + IF(is_pure_nnn=1,0,property_tax_annual+insurance_annual))) - (-PMT(0.07/12,loan_amortization_years*12,purchase_price*loan_to_value)*12) | G28: =(9000*12 - (9000*12*mgmt_fee_pct_of_rent + rm_annual + misc_annual + IF(is_pure_nnn=1,0,property_tax_annual+insurance_annual))) - (-PMT(0.075/12,loan_amortization_years*12,purchase_price*loan_to_value)*12) | H28: =(9000*12 - (9000*12*mgmt_fee_pct_of_rent + rm_annual + misc_annual + IF(is_pure_nnn=1,0,property_tax_annual+insurance_annual))) - (-PMT(0.08/12,loan_amortization_years*12,purchase_price*loan_to_value)*12) | I28: =(9000*12 - (9000*12*mgmt_fee_pct_of_rent + rm_annual + misc_annual + IF(is_pure_nnn=1,0,property_tax_annual+insurance_annual))) - (-PMT(0.085/12,loan_amortization_years*12,purchase_price*loan_to_value)*12) | J28: =(9000*12 - (9000*12*mgmt_fee_pct_of_rent + rm_annual + misc_annual + IF(is_pure_nnn=1,0,property_tax_annual+insurance_annual))) - (-PMT(0.09/12,loan_amortization_years*12,purchase_price*loan_to_value)*12) | K28: =(9000*12 - (9000*12*mgmt_fee_pct_of_rent + rm_annual + misc_annual + IF(is_pure_nnn=1,0,property_tax_annual+insurance_annual))) - (-PMT(0.095/12,loan_amortization_years*12,purchase_price*loan_to_value)*12) | L28: =(9000*12 - (9000*12*mgmt_fee_pct_of_rent + rm_annual + misc_annual + IF(is_pure_nnn=1,0,property_tax_annual+insurance_annual))) - (-PMT(0.1/12,loan_amortization_years*12,purchase_price*loan_to_value)*12)
A29: 9500 | B29: =(9500*12 - (9500*12*mgmt_fee_pct_of_rent + rm_annual + misc_annual + IF(is_pure_nnn=1,0,property_tax_annual+insurance_annual))) - (-PMT(0.05/12,loan_amortization_years*12,purchase_price*loan_to_value)*12) | C29: =(9500*12 - (9500*12*mgmt_fee_pct_of_rent + rm_annual + misc_annual + IF(is_pure_nnn=1,0,property_tax_annual+insurance_annual))) - (-PMT(0.055/12,loan_amortization_years*12,purchase_price*loan_to_value)*12) | D29: =(9500*12 - (9500*12*mgmt_fee_pct_of_rent + rm_annual + misc_annual + IF(is_pure_nnn=1,0,property_tax_annual+insurance_annual))) - (-PMT(0.06/12,loan_amortization_years*12,purchase_price*loan_to_value)*12) | E29: =(9500*12 - (9500*12*mgmt_fee_pct_of_rent + rm_annual + misc_annual + IF(is_pure_nnn=1,0,property_tax_annual+insurance_annual))) - (-PMT(0.065/12,loan_amortization_years*12,purchase_price*loan_to_value)*12) | F29: =(9500*12 - (9500*12*mgmt_fee_pct_of_rent + rm_annual + misc_annual + IF(is_pure_nnn=1,0,property_tax_annual+insurance_annual))) - (-PMT(0.07/12,loan_amortization_years*12,purchase_price*loan_to_value)*12) | G29: =(9500*12 - (9500*12*mgmt_fee_pct_of_rent + rm_annual + misc_annual + IF(is_pure_nnn=1,0,property_tax_annual+insurance_annual))) - (-PMT(0.075/12,loan_amortization_years*12,purchase_price*loan_to_value)*12) | H29: =(9500*12 - (9500*12*mgmt_fee_pct_of_rent + rm_annual + misc_annual + IF(is_pure_nnn=1,0,property_tax_annual+insurance_annual))) - (-PMT(0.08/12,loan_amortization_years*12,purchase_price*loan_to_value)*12) | I29: =(9500*12 - (9500*12*mgmt_fee_pct_of_rent + rm_annual + misc_annual + IF(is_pure_nnn=1,0,property_tax_annual+insurance_annual))) - (-PMT(0.085/12,loan_amortization_years*12,purchase_price*loan_to_value)*12) | J29: =(9500*12 - (9500*12*mgmt_fee_pct_of_rent + rm_annual + misc_annual + IF(is_pure_nnn=1,0,property_tax_annual+insurance_annual))) - (-PMT(0.09/12,loan_amortization_years*12,purchase_price*loan_to_value)*12) | K29: =(9500*12 - (9500*12*mgmt_fee_pct_of_rent + rm_annual + misc_annual + IF(is_pure_nnn=1,0,property_tax_annual+insurance_annual))) - (-PMT(0.095/12,loan_amortization_years*12,purchase_price*loan_to_value)*12) | L29: =(9500*12 - (9500*12*mgmt_fee_pct_of_rent + rm_annual + misc_annual + IF(is_pure_nnn=1,0,property_tax_annual+insurance_annual))) - (-PMT(0.1/12,loan_amortization_years*12,purchase_price*loan_to_value)*12)
